Workbook

Sheet REBUILT
A1: courses long | B1: courses short | C1: city | D1: county | E1: Type | F1: google rating | G1: slope | H1: latitude | I1: longitude
A2: Bay Pointe Golf Club | B2: Bay Pointe | C2: =VLOOKUP($B2, 'Main Data'!$B$2:$Z$131, 2, FALSE) -> West Bloomfield Township | D2: =VLOOKUP(B2, County!$A$2:$B$131, 2, FALSE) -> Oakland | E2: =VLOOKUP($B2, 'Main Data'!$B$2:$Z$131, 4, FALSE) -> Public | F2: =VLOOKUP(A2,'Google Ratings'!$A$2:$B$128, 2, FALSE) -> 3.9 | G2: =VLOOKUP($A2, 'Slope Ratings'!$A$2:$D$150, 3, FALSE) -> 121 | H2: =VLOOKUP($A2, 'course_coordinates (1)'!$A$2:$D$145, 4, FALSE) -> 42.582024 | I2: =VLOOKUP($A2, 'course_coordinates (1)'!$A$2:$G$145, 5, FALSE) -> -83.439877
A3: Beacon Hill Golf Club | B3: Beacon Hill | C3: =VLOOKUP($B3, 'Main Data'!$B$2:$Z$131, 2, FALSE) -> Commerce Township | D3: =VLOOKUP(B3, County!$A$2:$B$131, 2, FALSE) -> Oakland | E3: =VLOOKUP($B3, 'Main Data'!$B$2:$Z$131, 4, FALSE) -> Public | F3: =VLOOKUP(A3,'Google Ratings'!$A$2:$B$128, 2, FALSE) -> 4.3 | G3: =VLOOKUP($A3, 'Slope Ratings'!$A$2:$D$150, 3, FALSE) -> 126 | H3: =VLOOKUP($A3, 'course_coordinates (1)'!$A$2:$D$145, 4, FALSE) -> 42.608393 | I3: =VLOOKUP($A3, 'course_coordinates (1)'!$A$2:$G$145, 5, FALSE) -> -83.532568
A4: Bee Tee Golf Course | B4: Bee Tee | C4: =VLOOKUP($B4, 'Main Data'!$B$2:$Z$131, 2, FALSE) -> Macomb | D4: =VLOOKUP(B4, County!$A$2:$B$131, 2, FALSE) -> Macomb | E4: =VLOOKUP($B4, 'Main Data'!$B$2:$Z$131, 4, FALSE) -> Public | F4: =VLOOKUP(A4,'Google Ratings'!$A$2:$B$128, 2, FALSE) -> 3.7 | G4: =VLOOKUP($A4, 'Slope Ratings'!$A$2:$D$150, 3, FALSE) -> 132 | H4: =VLOOKUP($A4, 'course_coordinates (1)'!$A$2:$D$145, 4, FALSE) -> 42.647578 | I4: =VLOOKUP($A4, 'course_coordinates (1)'!$A$2:$G$145, 5, FALSE) -> -82.88073
A5: Bello Woods Golf Course | B5: Bello Woods | C5: =VLOOKUP($B5, 'Main Data'!$B$2:$Z$131, 2, FALSE) -> Macomb | D5: =VLOOKUP(B5, County!$A$2:$B$131, 2, FALSE) -> Macomb | E5: =VLOOKUP($B5, 'Main Data'!$B$2:$Z$131, 4, FALSE) -> Public | F5: =VLOOKUP(A5,'Google Ratings'!$A$2:$B$128, 2, FALSE) -> 3.9 | G5: =VLOOKUP($A5, 'Slope Ratings'!$A$2:$D$150, 3, FALSE) -> 110 | H5: =VLOOKUP($A5, 'course_coordinates (1)'!$A$2:$D$145, 4, FALSE) -> 42.672508 | I5: =VLOOKUP($A5, 'course_coordinates (1)'!$A$2:$G$145, 5, FALSE) -> -82.871765
A6: Birmingham Country Club | B6: Birmingham CC | C6: =VLOOKUP($B6, 'Main Data'!$B$2:$Z$131, 2, FALSE) -> Birmingham | D6: =VLOOKUP(B6, County!$A$2:$B$131, 2, FALSE) -> Oakland | E6: =VLOOKUP($B6, 'Main Data'!$B$2:$Z$131, 4, FALSE) -> Private | F6: =VLOOKUP(A6,'Google Ratings'!$A$2:$B$128, 2, FALSE) -> 4.7 | G6: =VLOOKUP($A6, 'Slope Ratings'!$A$2:$D$150, 3, FALSE) -> 129 | H6: =VLOOKUP($A6, 'course_coordinates (1)'!$A$2:$D$145, 4, FALSE) -> 42.533127 | I6: =VLOOKUP($A6, 'course_coordinates (1)'!$A$2:$G$145, 5, FALSE) -> -83.234329
A7: Blackheath Golf Club | B7: Blackheath | C7: =VLOOKUP($B7, 'Main Data'!$B$2:$Z$131, 2, FALSE) -> Oakland Township | D7: =VLOOKUP(B7, County!$A$2:$B$131, 2, FALSE) -> Oakland | E7: =VLOOKUP($B7, 'Main Data'!$B$2:$Z$131, 4, FALSE) -> Public | F7: =VLOOKUP(A7,'Google Ratings'!$A$2:$B$128, 2, FALSE) -> 3.7 | G7: =VLOOKUP($A7, 'Slope Ratings'!$A$2:$D$150, 3, FALSE) -> 125 | H7: =VLOOKUP($A7, 'course_coordinates (1)'!$A$2:$D$145, 4, FALSE) -> 42.751564 | I7: =VLOOKUP($A7, 'course_coordinates (1)'!$A$2:$G$145, 5, FALSE) -> -83.134468
A8: Bloomfield Hills Country Club | B8: Bloomfield Hills CC | C8: =VLOOKUP($B8, 'Main Data'!$B$2:$Z$131, 2, FALSE) -> Bloomfield Hills | D8: =VLOOKUP(B8, County!$A$2:$B$131, 2, FALSE) -> Oakland | E8: =VLOOKUP($B8, 'Main Data'!$B$2:$Z$131, 4, FALSE) -> Private | F8: =VLOOKUP(A8,'Google Ratings'!$A$2:$B$128, 2, FALSE) -> 4.4 | G8: =VLOOKUP($A8, 'Slope Ratings'!$A$2:$D$150, 3, FALSE) -> 128 | H8: =VLOOKUP($A8, 'course_coordinates (1)'!$A$2:$D$145, 4, FALSE) -> 42.582906 | I8: =VLOOKUP($A8, 'course_coordinates (1)'!$A$2:$G$145, 5, FALSE) -> -83.252639
A9: Boulder Pointe Golf Club | B9: Boulder Pointe | C9: =VLOOKUP($B9, 'Main Data'!$B$2:$Z$131, 2, FALSE) -> Oxford | D9: =VLOOKUP(B9, County!$A$2:$B$131, 2, FALSE) -> Oakland | E9: =VLOOKUP($B9, 'Main Data'!$B$2:$Z$131, 4, FALSE) -> Public | F9: =VLOOKUP(A9,'Google Ratings'!$A$2:$B$128, 2, FALSE) -> 4.3 | G9: =VLOOKUP($A9, 'Slope Ratings'!$A$2:$D$150, 3, FALSE) -> 130 | H9: =VLOOKUP($A9, 'course_coordinates (1)'!$A$2:$D$145, 4, FALSE) -> 42.834254 | I9: =VLOOKUP($A9, 'course_coordinates (1)'!$A$2:$G$145, 5, FALSE) -> -83.277656
A10: Brae Burn Golf Club | B10: Brae Burn | C10: =VLOOKUP($B10, 'Main Data'!$B$2:$Z$131, 2, FALSE) -> Plymouth Township | D10: =VLOOKUP(B10, County!$A$2:$B$131, 2, FALSE) -> Wayne | E10: =VLOOKUP($B10, 'Main Data'!$B$2:$Z$131, 4, FALSE) -> Public | F10: =VLOOKUP(A10,'Google Ratings'!$A$2:$B$128, 2, FALSE) -> 3.7 | G10: =VLOOKUP($A10, 'Slope Ratings'!$A$2:$D$150, 3, FALSE) -> 123 | H10: =VLOOKUP($A10, 'course_coordinates (1)'!$A$2:$D$145, 4, FALSE) -> 42.391292 | I10: =VLOOKUP($A10, 'course_coordinates (1)'!$A$2:$G$145, 5, FALSE) -> -83.551051
A11: Brentwood Golf Club | B11: Brentwood | C11: =VLOOKUP($B11, 'Main Data'!$B$2:$Z$131, 2, FALSE) -> White Lake | D11: =VLOOKUP(B11, County!$A$2:$B$131, 2, FALSE) -> Oakland | E11: =VLOOKUP($B11, 'Main Data'!$B$2:$Z$131, 4, FALSE) -> Public | F11: =VLOOKUP(A11,'Google Ratings'!$A$2:$B$128, 2, FALSE) -> 4.1 | G11: =VLOOKUP($A11, 'Slope Ratings'!$A$2:$D$150, 3, FALSE) -> 119 | H11: =VLOOKUP($A11, 'course_coordinates (1)'!$A$2:$D$145, 4, FALSE) -> 42.618441 | I11: =VLOOKUP($A11, 'course_coordinates (1)'!$A$2:$G$145, 5, FALSE) -> -83.525783
A12: Brookwood | B12: Brookwood | C12: =VLOOKUP($B12, 'Main Data'!$B$2:$Z$131, 2, FALSE) -> Rochester Hills | D12: =VLOOKUP(B12, County!$A$2:$B$131, 2, FALSE) -> Oakland | E12: =VLOOKUP($B12, 'Main Data'!$B$2:$Z$131, 4, FALSE) -> Private | F12: =VLOOKUP(A12,'Google Ratings'!$A$2:$B$128, 2, FALSE) -> 4.6 | G12: 125 | H12: 42.69397 | I12: -83.17477
A13: Bruce Hills Public Golf Course | B13: Bruce Hills | C13: =VLOOKUP($B13, 'Main Data'!$B$2:$Z$131, 2, FALSE) -> Bruce Township | D13: =VLOOKUP(B13, County!$A$2:$B$131, 2, FALSE) -> Macomb | E13: =VLOOKUP($B13, 'Main Data'!$B$2:$Z$131, 4, FALSE) -> Public | F13: =VLOOKUP(A13,'Google Ratings'!$A$2:$B$128, 2, FALSE) -> 3.8 | G13: =VLOOKUP($A13, 'Slope Ratings'!$A$2:$D$150, 3, FALSE) -> 106 | H13: =VLOOKUP($A13, 'course_coordinates (1)'!$A$2:$D$145, 4, FALSE) -> 42.824 | I13: =VLOOKUP($A13, 'course_coordinates (1)'!$A$2:$G$145, 5, FALSE) -> -83.051683
A14: Bushwood Golf Course | B14: Bushwood | C14: =VLOOKUP($B14, 'Main Data'!$B$2:$Z$131, 2, FALSE) -> Northville | D14: Wayne | E14: =VLOOKUP($B14, 'Main Data'!$B$2:$Z$131, 4, FALSE) -> Public | F14: =VLOOKUP(A14,'Google Ratings'!$A$2:$B$128, 2, FALSE) -> 4.3 | G14: 90 | H14: =VLOOKUP($A14, 'course_coordinates (1)'!$A$2:$D$145, 4, FALSE) -> 42.405417 | I14: =VLOOKUP($A14, 'course_coordinates (1)'!$A$2:$G$145, 5, FALSE) -> -83.433615
A15: Cedar Glen Golf and Outing | B15: Cedar Glen | C15: =VLOOKUP($B15, 'Main Data'!$B$2:$Z$131, 2, FALSE) -> New Baltimore | D15: =VLOOKUP(B15, County!$A$2:$B$131, 2, FALSE) -> Macomb | E15: =VLOOKUP($B15, 'Main Data'!$B$2:$Z$131, 4, FALSE) -> Public | F15: =VLOOKUP(A15,'Google Ratings'!$A$2:$B$128, 2, FALSE) -> 3.7 | G15: =VLOOKUP($A15, 'Slope Ratings'!$A$2:$D$150, 3, FALSE) -> 116 | H15: =VLOOKUP($A15, 'course_coordinates (1)'!$A$2:$D$145, 4, FALSE) -> 42.705367 | I15: =VLOOKUP($A15, 'course_coordinates (1)'!$A$2:$G$145, 5, FALSE) -> -82.747159
A16: Chandler Park Golf Course | B16: Chandler Park | C16: =VLOOKUP($B16, 'Main Data'!$B$2:$Z$131, 2, FALSE) -> Detroit | D16: =VLOOKUP(B16, County!$A$2:$B$131, 2, FALSE) -> Wayne | E16: =VLOOKUP($B16, 'Main Data'!$B$2:$Z$131, 4, FALSE) -> Public | F16: =VLOOKUP(A16,'Google Ratings'!$A$2:$B$128, 2, FALSE) -> 4.2 | G16: =VLOOKUP($A16, 'Slope Ratings'!$A$2:$D$150, 3, FALSE) -> 104 | H16: =VLOOKUP($A16, 'course_coordinates (1)'!$A$2:$D$145, 4, FALSE) -> 42.397154 | I16: =VLOOKUP($A16, 'course_coordinates (1)'!$A$2:$G$145, 5, FALSE) -> -82.97287
A17: Cherry Creek Golf Club | B17: Cherry Creek | C17: =VLOOKUP($B17, 'Main Data'!$B$2:$Z$131, 2, FALSE) -> Shelby Township | D17: =VLOOKUP(B17, County!$A$2:$B$131, 2, FALSE) -> Macomb | E17: =VLOOKUP($B17, 'Main Data'!$B$2:$Z$131, 4, FALSE) -> Public | F17: =VLOOKUP(A17,'Google Ratings'!$A$2:$B$128, 2, FALSE) -> 4.5 | G17: =VLOOKUP($A17, 'Slope Ratings'!$A$2:$D$150, 3, FALSE) -> 124 | H17: =VLOOKUP($A17, 'course_coordinates (1)'!$A$2:$D$145, 4, FALSE) -> 42.676976 | I17: =VLOOKUP($A17, 'course_coordinates (1)'!$A$2:$G$145, 5, FALSE) -> -83.021367
A18: Copper Creek Golf Course | B18: Copper Creek | C18: =VLOOKUP($B18, 'Main Data'!$B$2:$Z$131, 2, FALSE) -> Farmington Hills | D18: =VLOOKUP(B18, County!$A$2:$B$131, 2, FALSE) -> Oakland | E18: =VLOOKUP($B18, 'Main Data'!$B$2:$Z$131, 4, FALSE) -> Public | F18: =VLOOKUP(A18,'Google Ratings'!$A$2:$B$128, 2, FALSE) -> 4.2 | G18: =VLOOKUP($A18, 'Slope Ratings'!$A$2:$D$150, 3, FALSE) -> 114 | H18: =VLOOKUP($A18, 'course_coordinates (1)'!$A$2:$D$145, 4, FALSE) -> 42.498356 | I18: =VLOOKUP($A18, 'course_coordinates (1)'!$A$2:$G$145, 5, FALSE) -> -83.424146
A19: Copper Hills Golf Club | B19: Copper Hills | C19: =VLOOKUP($B19, 'Main Data'!$B$2:$Z$131, 2, FALSE) -> Oxford | D19: =VLOOKUP(B19, County!$A$2:$B$131, 2, FALSE) -> Oakland | E19: =VLOOKUP($B19, 'Main Data'!$B$2:$Z$131, 4, FALSE) -> Public | F19: =VLOOKUP(A19,'Google Ratings'!$A$2:$B$128, 2, FALSE) -> 3.9 | G19: =VLOOKUP($A19, 'Slope Ratings'!$A$2:$D$150, 3, FALSE) -> 134 | H19: =VLOOKUP($A19, 'course_coordinates (1)'!$A$2:$D$145, 4, FALSE) -> 42.82732 | I19: =VLOOKUP($A19, 'course_coordinates (1)'!$A$2:$G$145, 5, FALSE) -> -83.182912
A20: Country Club of Detroit | B20: Country Club of Detroit | C20: =VLOOKUP($B20, 'Main Data'!$B$2:$Z$131, 2, FALSE) -> Grosse Pointe Farms | D20: =VLOOKUP(B20, County!$A$2:$B$131, 2, FALSE) -> Wayne | E20: =VLOOKUP($B20, 'Main Data'!$B$2:$Z$131, 4, FALSE) -> Private | F20: =VLOOKUP(A20,'Google Ratings'!$A$2:$B$128, 2, FALSE) -> 4.6 | G20: =VLOOKUP($A20, 'Slope Ratings'!$A$2:$D$150, 3, FALSE) -> 131 | H20: =VLOOKUP($A20, 'course_coordinates (1)'!$A$2:$D$145, 4, FALSE) -> 42.414724 | I20: =VLOOKUP($A20, 'course_coordinates (1)'!$A$2:$G$145, 5, FALSE) -> -82.894073
A21: Coyote Golf Club | B21: Coyote | C21: =VLOOKUP($B21, 'Main Data'!$B$2:$Z$131, 2, FALSE) -> New Hudson | D21: =VLOOKUP(B21, County!$A$2:$B$131, 2, FALSE) -> Oakland | E21: =VLOOKUP($B21, 'Main Data'!$B$2:$Z$131, 4, FALSE) -> Public | F21: =VLOOKUP(A21,'Google Ratings'!$A$2:$B$128, 2, FALSE) -> 4.1 | G21: =VLOOKUP($A21, 'Slope Ratings'!$A$2:$D$150, 3, FALSE) -> 133 | H21: =VLOOKUP($A21, 'course_coordinates (1)'!$A$2:$D$145, 4, FALSE) -> 42.497571 | I21: =VLOOKUP($A21, 'course_coordinates (1)'!$A$2:$G$145, 5, FALSE) -> -83.612396
A22: Cracklewood Golf Club | B22: Cracklewood | C22: =VLOOKUP($B22, 'Main Data'!$B$2:$Z$131, 2, FALSE) -> Macomb | D22: =VLOOKUP(B22, County!$A$2:$B$131, 2, FALSE) -> Macomb | E22: =VLOOKUP($B22, 'Main Data'!$B$2:$Z$131, 4, FALSE) -> Public | F22: =VLOOKUP(A22,'Google Ratings'!$A$2:$B$128, 2, FALSE) -> 3.9 | G22: =VLOOKUP($A22, 'Slope Ratings'!$A$2:$D$150, 3, FALSE) -> 121 | H22: =VLOOKUP($A22, 'course_coordinates (1)'!$A$2:$D$145, 4, FALSE) -> 42.689617 | I22: =VLOOKUP($A22, 'course_coordinates (1)'!$A$2:$G$145, 5, FALSE) -> -82.942924
A23: Dearborn Country Club | B23: Dearborn CC | C23: =VLOOKUP($B23, 'Main Data'!$B$2:$Z$131, 2, FALSE) -> Dearborn | D23: =VLOOKUP(B23, County!$A$2:$B$131, 2, FALSE) -> Wayne | E23: =VLOOKUP($B23, 'Main Data'!$B$2:$Z$131, 4, FALSE) -> Private | F23: =VLOOKUP(A23,'Google Ratings'!$A$2:$B$128, 2, FALSE) -> 4.5 | G23: =VLOOKUP($A23, 'Slope Ratings'!$A$2:$D$150, 3, FALSE) -> 124 | H23: =VLOOKUP($A23, 'course_coordinates (1)'!$A$2:$D$145, 4, FALSE) -> 42.317751 | I23: =VLOOKUP($A23, 'course_coordinates (1)'!$A$2:$G$145, 5, FALSE) -> -83.254531
A24: Dearborn Hills Golf Course | B24: Dearborn Hills | C24: =VLOOKUP($B24, 'Main Data'!$B$2:$Z$131, 2, FALSE) -> Dearborn | D24: =VLOOKUP(B24, County!$A$2:$B$131, 2, FALSE) -> Wayne | E24: =VLOOKUP($B24, 'Main Data'!$B$2:$Z$131, 4, FALSE) -> Public | F24: =VLOOKUP(A24,'Google Ratings'!$A$2:$B$128, 2, FALSE) -> 3.6 | G24: 100 | H24: =VLOOKUP($A24, 'course_coordinates (1)'!$A$2:$D$145, 4, FALSE) -> 42.301256 | I24: =VLOOKUP($A24, 'course_coordinates (1)'!$A$2:$G$145, 5, FALSE) -> -83.273568
A25: Detroit Golf Club | B25: Detroit Golf Club | C25: =VLOOKUP($B25, 'Main Data'!$B$2:$Z$131, 2, FALSE) -> Detroit | D25: =VLOOKUP(B25, County!$A$2:$B$131, 2, FALSE) -> Wayne | E25: =VLOOKUP($B25, 'Main Data'!$B$2:$Z$131, 4, FALSE) -> Private | F25: =VLOOKUP(A25,'Google Ratings'!$A$2:$B$128, 2, FALSE) -> 4.7 | G25: =VLOOKUP($A25, 'Slope Ratings'!$A$2:$D$150, 3, FALSE) -> 125 | H25: =VLOOKUP($A25, 'course_coordinates (1)'!$A$2:$D$145, 4, FALSE) -> 42.42628 | I25: =VLOOKUP($A25, 'course_coordinates (1)'!$A$2:$G$145, 5, FALSE) -> -83.126246
A26: Downing Farms Golf Course | B26: Downing Farms | C26: =VLOOKUP($B26, 'Main Data'!$B$2:$Z$131, 2, FALSE) -> Northville | D26: =VLOOKUP(B26, County!$A$2:$B$131, 2, FALSE) -> Wayne | E26: =VLOOKUP($B26, 'Main Data'!$B$2:$Z$131, 4, FALSE) -> Public | F26: =VLOOKUP(A26,'Google Ratings'!$A$2:$B$128, 2, FALSE) -> 3.8 | G26: =VLOOKUP($A26, 'Slope Ratings'!$A$2:$D$150, 3, FALSE) -> 115 | H26: =VLOOKUP($A26, 'course_coordinates (1)'!$A$2:$D$145, 4, FALSE) -> 42.418376 | I26: =VLOOKUP($A26, 'course_coordinates (1)'!$A$2:$G$145, 5, FALSE) -> -83.604452
A27: Edgewood Country Club | B27: Edgewood | C27: =VLOOKUP($B27, 'Main Data'!$B$2:$Z$131, 2, FALSE) -> Commerce Township | D27: =VLOOKUP(B27, County!$A$2:$B$131, 2, FALSE) -> Oakland | E27: =VLOOKUP($B27, 'Main Data'!$B$2:$Z$131, 4, FALSE) -> Private | F27: =VLOOKUP(A27,'Google Ratings'!$A$2:$B$128, 2, FALSE) -> 4.7 | G27: =VLOOKUP($A27, 'Slope Ratings'!$A$2:$D$150, 3, FALSE) -> 128 | H27: =VLOOKUP($A27, 'course_coordinates (1)'!$A$2:$D$145, 4, FALSE) -> 42.589848 | I27: =VLOOKUP($A27, 'course_coordinates (1)'!$A$2:$G$145, 5, FALSE) -> -83.450099
A28: Evergreen Hills Golf Course | B28: Evergreen Hills | C28: =VLOOKUP($B28, 'Main Data'!$B$2:$Z$131, 2, FALSE) -> Southfield | D28: =VLOOKUP(B28, County!$A$2:$B$131, 2, FALSE) -> Oakland | E28: =VLOOKUP($B28, 'Main Data'!$B$2:$Z$131, 4, FALSE) -> Public | F28: =VLOOKUP(A28,'Google Ratings'!$A$2:$B$128, 2, FALSE) -> 4 | G28: =VLOOKUP($A28, 'Slope Ratings'!$A$2:$D$150, 3, FALSE) -> 108 | H28: =VLOOKUP($A28, 'course_coordinates (1)'!$A$2:$D$145, 4, FALSE) -> 42.479117 | I28: =VLOOKUP($A28, 'course_coordinates (1)'!$A$2:$G$145, 5, FALSE) -> -83.235713
A29: Farmington Hills Golf Club | B29: Farmington Hills | C29: =VLOOKUP($B29, 'Main Data'!$B$2:$Z$131, 2, FALSE) -> Farmington Hills | D29: =VLOOKUP(B29, County!$A$2:$B$131, 2, FALSE) -> Oakland | E29: =VLOOKUP($B29, 'Main Data'!$B$2:$Z$131, 4, FALSE) -> Public | F29: =VLOOKUP(A29,'Google Ratings'!$A$2:$B$128, 2, FALSE) -> 4.2 | G29: =VLOOKUP($A29, 'Slope Ratings'!$A$2:$D$150, 3, FALSE) -> 118 | H29: =VLOOKUP($A29, 'course_coordinates (1)'!$A$2:$D$145, 4, FALSE) -> 42.482576 | I29: =VLOOKUP($A29, 'course_coordinates (1)'!$A$2:$G$145, 5, FALSE) -> -83.419117
A30: Fellows Creek Golf Club | B30: Fellows Creek | C30: =VLOOKUP($B30, 'Main Data'!$B$2:$Z$131, 2, FALSE) -> Canton Township | D30: =VLOOKUP(B30, County!$A$2:$B$131, 2, FALSE) -> Wayne | E30: =VLOOKUP($B30, 'Main Data'!$B$2:$Z$131, 4, FALSE) -> Public | F30: =VLOOKUP(A30,'Google Ratings'!$A$2:$B$128, 2, FALSE) -> 4.2 | G30: =VLOOKUP($A30, 'Slope Ratings'!$A$2:$D$150, 3, FALSE) -> 119 | H30: =VLOOKUP($A30, 'course_coordinates (1)'!$A$2:$D$145, 4, FALSE) -> 42.286169 | I30: =VLOOKUP($A30, 'course_coordinates (1)'!$A$2:$G$145, 5, FALSE) -> -83.43872
A31: Fern Hill Golf Club | B31: Fern Hill | C31: =VLOOKUP($B31, 'Main Data'!$B$2:$Z$131, 2, FALSE) -> Clinton Township | D31: =VLOOKUP(B31, County!$A$2:$B$131, 2, FALSE) -> Macomb | E31: =VLOOKUP($B31, 'Main Data'!$B$2:$Z$131, 4, FALSE) -> Public | F31: =VLOOKUP(A31,'Google Ratings'!$A$2:$B$128, 2, FALSE) -> 4.1 | G31: =VLOOKUP($A31, 'Slope Ratings'!$A$2:$D$150, 3, FALSE) -> 112 | H31: =VLOOKUP($A31, 'course_coordinates (1)'!$A$2:$D$145, 4, FALSE) -> 42.582209 | I31: =VLOOKUP($A31, 'course_coordinates (1)'!$A$2:$G$145, 5, FALSE) -> -82.942197
A32: Fieldstone Golf Club | B32: Fieldstone | C32: =VLOOKUP($B32, 'Main Data'!$B$2:$Z$131, 2, FALSE) -> Auburn Hills | D32: =VLOOKUP(B32, County!$A$2:$B$131, 2, FALSE) -> Oakland | E32: =VLOOKUP($B32, 'Main Data'!$B$2:$Z$131, 4, FALSE) -> Public | F32: =VLOOKUP(A32,'Google Ratings'!$A$2:$B$128, 2, FALSE) -> 3.9 | G32: =VLOOKUP($A32, 'Slope Ratings'!$A$2:$D$150, 3, FALSE) -> 134 | H32: =VLOOKUP($A32, 'course_coordinates (1)'!$A$2:$D$145, 4, FALSE) -> 42.688153 | I32: =VLOOKUP($A32, 'course_coordinates (1)'!$A$2:$G$145, 5, FALSE) -> -83.25631
A33: Forest Lake Country Club | B33: Forest Lake | C33: =VLOOKUP($B33, 'Main Data'!$B$2:$Z$131, 2, FALSE) -> Bloomfield Township | D33: =VLOOKUP(B33, County!$A$2:$B$131, 2, FALSE) -> Oakland | E33: =VLOOKUP($B33, 'Main Data'!$B$2:$Z$131, 4, FALSE) -> Private | F33: =VLOOKUP(A33,'Google Ratings'!$A$2:$B$128, 2, FALSE) -> 4.6 | G33: =VLOOKUP($A33, 'Slope Ratings'!$A$2:$D$150, 3, FALSE) -> 132 | H33: =VLOOKUP($A33, 'course_coordinates (1)'!$A$2:$D$145, 4, FALSE) -> 42.596914 | I33: =VLOOKUP($A33, 'course_coordinates (1)'!$A$2:$G$145, 5, FALSE) -> -83.297174
A34: Fountains Golf & Banquet | B34: Fountains | C34: =VLOOKUP($B34, 'Main Data'!$B$2:$Z$131, 2, FALSE) -> Village of Clarkston | D34: =VLOOKUP(B34, County!$A$2:$B$131, 2, FALSE) -> Oakland | E34: =VLOOKUP($B34, 'Main Data'!$B$2:$Z$131, 4, FALSE) -> Public | F34: =VLOOKUP(A34,'Google Ratings'!$A$2:$B$128, 2, FALSE) -> 4.4 | G34: =VLOOKUP($A34, 'Slope Ratings'!$A$2:$D$150, 3, FALSE) -> 119 | H34: =VLOOKUP($A34, 'course_coordinates (1)'!$A$2:$D$145, 4, FALSE) -> 42.719551 | I34: =VLOOKUP($A34, 'course_coordinates (1)'!$A$2:$G$145, 5, FALSE) -> -83.390629
A35: Fox Creek Golf Course | B35: Fox Creek | C35: =VLOOKUP($B35, 'Main Data'!$B$2:$Z$131, 2, FALSE) -> Livonia | D35: =VLOOKUP(B35, County!$A$2:$B$131, 2, FALSE) -> Wayne | E35: =VLOOKUP($B35, 'Main Data'!$B$2:$Z$131, 4, FALSE) -> Public | F35: =VLOOKUP(A35,'Google Ratings'!$A$2:$B$128, 2, FALSE) -> 4.4 | G35: =VLOOKUP($A35, 'Slope Ratings'!$A$2:$D$150, 3, FALSE) -> 118 | H35: =VLOOKUP($A35, 'course_coordinates (1)'!$A$2:$D$145, 4, FALSE) -> 42.427213 | I35: =VLOOKUP($A35, 'course_coordinates (1)'!$A$2:$G$145, 5, FALSE) -> -83.398248
A36: Fox Hills Golf & Banquet Center | B36: Fox Hills | C36: =VLOOKUP($B36, 'Main Data'!$B$2:$Z$131, 2, FALSE) -> Plymouth | D36: =VLOOKUP(B36, County!$A$2:$B$131, 2, FALSE) -> Wayne | E36: =VLOOKUP($B36, 'Main Data'!$B$2:$Z$131, 4, FALSE) -> Public | F36: =VLOOKUP(A36,'Google Ratings'!$A$2:$B$128, 2, FALSE) -> 4.6 | G36: =VLOOKUP($A36, 'Slope Ratings'!$A$2:$D$150, 3, FALSE) -> 125 | H36: =VLOOKUP($A36, 'course_coordinates (1)'!$A$2:$D$145, 4, FALSE) -> 42.362859 | I36: =VLOOKUP($A36, 'course_coordinates (1)'!$A$2:$G$145, 5, FALSE) -> -83.593107
... A38: Gateway Golf Club | B38: Gateway | C38: =VLOOKUP($B38, 'Main Data'!$B$2:$Z$131, 2, FALSE) -> Romulus | D38: =VLOOKUP(B38, County!$A$2:$B$131, 2, FALSE) -> Wayne | E38: =VLOOKUP($B38, 'Main Data'!$B$2:$Z$131, 4, FALSE) -> Public | F38: =VLOOKUP(A38,'Google Ratings'!$A$2:$B$128, 2, FALSE) -> 4.2 | G38: =VLOOKUP($A38, 'Slope Ratings'!$A$2:$D$150, 3, FALSE) -> 128 | H38: =VLOOKUP($A38, 'course_coordinates (1)'!$A$2:$D$145, 4, FALSE) -> 42.266574 | I38: =VLOOKUP($A38, 'course_coordinates (1)'!$A$2:$G$145, 5, FALSE) -> -83.363128
A39: Glacier Club | B39: Glacier Club | C39: =VLOOKUP($B39, 'Main Data'!$B$2:$Z$131, 2, FALSE) -> Washington | D39: =VLOOKUP(B39, County!$A$2:$B$131, 2, FALSE) -> Macomb | E39: =VLOOKUP($B39, 'Main Data'!$B$2:$Z$131, 4, FALSE) -> Public | F39: =VLOOKUP(A39,'Google Ratings'!$A$2:$B$128, 2, FALSE) -> 0 | G39: 126 | H39: =VLOOKUP($A39, 'course_coordinates (1)'!$A$2:$D$145, 4, FALSE) -> 42.735314 | I39: =VLOOKUP($A39, 'course_coordinates (1)'!$A$2:$G$145, 5, FALSE) -> -83.038512
A40: Glen Oaks Golf Course | B40: Glen Oaks | C40: =VLOOKUP($B40, 'Main Data'!$B$2:$Z$131, 2, FALSE) -> Farmington Hills | D40: =VLOOKUP(B40, County!$A$2:$B$131, 2, FALSE) -> Oakland | E40: =VLOOKUP($B40, 'Main Data'!$B$2:$Z$131, 4, FALSE) -> Public | F40: =VLOOKUP(A40,'Google Ratings'!$A$2:$B$128, 2, FALSE) -> 4.4 | G40: =VLOOKUP($A40, 'Slope Ratings'!$A$2:$D$150, 3, FALSE) -> 118 | H40: =VLOOKUP($A40, 'course_coordinates (1)'!$A$2:$D$145, 4, FALSE) -> 42.514367 | I40: =VLOOKUP($A40, 'course_coordinates (1)'!$A$2:$G$145, 5, FALSE) -> -83.352646
A41: Glenhurst Golf Course | B41: Glenhurst | C41: =VLOOKUP($B41, 'Main Data'!$B$2:$Z$131, 2, FALSE) -> Redford Township | D41: =VLOOKUP(B41, County!$A$2:$B$131, 2, FALSE) -> Wayne | E41: =VLOOKUP($B41, 'Main Data'!$B$2:$Z$131, 4, FALSE) -> Public | F41: =VLOOKUP(A41,'Google Ratings'!$A$2:$B$128, 2, FALSE) -> 4.3 | G41: =VLOOKUP($A41, 'Slope Ratings'!$A$2:$D$150, 3, FALSE) -> 109 | H41: =VLOOKUP($A41, 'course_coordinates (1)'!$A$2:$D$145, 4, FALSE) -> 42.41393 | I41: =VLOOKUP($A41, 'course_coordinates (1)'!$A$2:$G$145, 5, FALSE) -> -83.290976
...

Sheet Main Data
A1: # | B1: Golf Course | C1: city | D1: county | E1: type (provisional) | F1: google_rating | G1: Slope Rating | H1: google_reviews | I1: year_built | J1: latitude | K1: longitude | L1: latitude | M1: longitude | N1: Lookup
A2: 23 | B2: Bay Pointe | C2: West Bloomfield Township | D2: Oakland | E2: Public | F2: 3.9 | G2: =VLOOKUP(B2, 'Slope Ratings'!$A$2:$C$147, 2, TRUE) -> #N/A | H2: 211 | J2: 42.436413 | K2: -82.894256 | L2: =INDEX('course_coordinates (1)'!$D$2:$D$145,MATCH('Main Data'!N64,'course_coordinates (1)'!$A$2:$A$145,0)) -> 42.436413 | M2: =INDEX('course_coordinates (1)'!$E$2:$E$145,MATCH('Main Data'!N64,'course_coordinates (1)'!$A$2:$A$145,0)) -> -82.894256 | N2: Bay Pointe Golf Club
A3: 24 | B3: Beacon Hill | C3: Commerce Township | D3: Oakland | E3: Public | F3: 4.3 | G3: =VLOOKUP(B3, 'Slope Ratings'!$A$2:$C$147, 2, TRUE) -> #N/A | H3: 283 | J3: 42.543896 | K3: -83.277687 | L3: =INDEX('course_coordinates (1)'!$D$2:$D$145,MATCH('Main Data'!N75,'course_coordinates (1)'!$A$2:$A$145,0)) -> 42.543896 | M3: =INDEX('course_coordinates (1)'!$E$2:$E$145,MATCH('Main Data'!N75,'course_coordinates (1)'!$A$2:$A$145,0)) -> -83.277687 | N3: Beacon Hill Golf Club
A4: 82 | B4: Bee Tee | C4: Macomb | D4: Macomb | E4: Public | F4: 3.7 | G4: =VLOOKUP(B4, 'Slope Ratings'!$A$2:$C$147, 2, TRUE) -> #N/A | H4: 231 | J4: 42.589848 | K4: -83.450099 | L4: =INDEX('course_coordinates (1)'!$D$2:$D$145,MATCH('Main Data'!N23,'course_coordinates (1)'!$A$2:$A$145,0)) -> 42.589848 | M4: =INDEX('course_coordinates (1)'!$E$2:$E$145,MATCH('Main Data'!N23,'course_coordinates (1)'!$A$2:$A$145,0)) -> -83.450099 | N4: Bee Tee Golf Course
A5: 25 | B5: Bello Woods | C5: Macomb | D5: Macomb | E5: Public | F5: 3.9 | G5: =VLOOKUP(B5, 'Slope Ratings'!$A$2:$C$147, 2, TRUE) -> #N/A | H5: 401 | J5: 42.596914 | K5: -83.297174 | L5: =INDEX('course_coordinates (1)'!$D$2:$D$145,MATCH('Main Data'!N29,'course_coordinates (1)'!$A$2:$A$145,0)) -> 42.596914 | M5: =INDEX('course_coordinates (1)'!$E$2:$E$145,MATCH('Main Data'!N29,'course_coordinates (1)'!$A$2:$A$145,0)) -> -83.297174 | N5: Blackheath Golf Club
A6: 122 | B6: Birmingham CC | C6: Birmingham | D6: Oakland | E6: Private | F6: 4.7 | G6: =VLOOKUP(B6, 'Slope Ratings'!$A$2:$C$147, 2, TRUE) -> 121 | H6: 178 | J6: 42.608393 | K6: -83.532568 | L6: =INDEX('course_coordinates (1)'!$D$2:$D$145,MATCH('Main Data'!N3,'course_coordinates (1)'!$A$2:$A$145,0)) -> 42.608393 | M6: =INDEX('course_coordinates (1)'!$E$2:$E$145,MATCH('Main Data'!N3,'course_coordinates (1)'!$A$2:$A$145,0)) -> -83.532568 | N6: Bloomfield Hills Country Club
A7: 26 | B7: Blackheath | C7: Oakland Township | D7: Oakland | E7: Public | F7: 3.7 | G7: =VLOOKUP(B7, 'Slope Ratings'!$A$2:$C$147, 2, TRUE) -> 121 | H7: 377 | J7: 42.295347 | K7: -83.498548 | L7: =INDEX('course_coordinates (1)'!$D$2:$D$145,MATCH('Main Data'!N79,'course_coordinates (1)'!$A$2:$A$145,0)) -> 42.295347 | M7: =INDEX('course_coordinates (1)'!$E$2:$E$145,MATCH('Main Data'!N79,'course_coordinates (1)'!$A$2:$A$145,0)) -> -83.498548 | N7: Boulder Pointe Golf Club
A8: 74 | B8: Bloomfield Hills CC | C8: Bloomfield Hills | D8: Oakland | E8: Private | F8: 4.4 | G8: =VLOOKUP(B8, 'Slope Ratings'!$A$2:$C$147, 2, TRUE) -> 121 | H8: 121 | I8: 1913 | J8: 42.751564 | K8: -83.134468 | L8: =INDEX('course_coordinates (1)'!$D$2:$D$145,MATCH('Main Data'!N5,'course_coordinates (1)'!$A$2:$A$145,0)) -> 42.751564 | M8: =INDEX('course_coordinates (1)'!$E$2:$E$145,MATCH('Main Data'!N5,'course_coordinates (1)'!$A$2:$A$145,0)) -> -83.134468 | N8: Brae Burn Golf Club
A9: 27 | B9: Boulder Pointe | C9: Oxford | D9: Oakland | E9: Public | F9: 4.3 | G9: =VLOOKUP(B9, 'Slope Ratings'!$A$2:$C$147, 2, TRUE) -> 121 | H9: 502 | J9: 42.476184 | K9: -83.163585 | L9: =INDEX('course_coordinates (1)'!$D$2:$D$145,MATCH('Main Data'!N88,'course_coordinates (1)'!$A$2:$A$145,0)) -> 42.476184 | M9: =INDEX('course_coordinates (1)'!$E$2:$E$145,MATCH('Main Data'!N88,'course_coordinates (1)'!$A$2:$A$145,0)) -> -83.163585 | N9: Brentwood Golf Club
A10: 119 | B10: Brae Burn | C10: Plymouth Township | D10: Wayne | E10: Public | F10: 3.7 | G10: =VLOOKUP(B10, 'Slope Ratings'!$A$2:$C$147, 2, TRUE) -> 121 | H10: 243 | J10: 42.582906 | K10: -83.252639 | L10: =INDEX('course_coordinates (1)'!$D$2:$D$145,MATCH('Main Data'!N6,'course_coordinates (1)'!$A$2:$A$145,0)) -> 42.582906 | M10: =INDEX('course_coordinates (1)'!$E$2:$E$145,MATCH('Main Data'!N6,'course_coordinates (1)'!$A$2:$A$145,0)) -> -83.252639 | N10: Brookside Golf Course-Saline
A11: 66 | B11: Brentwood | C11: White Lake | D11: Oakland | E11: Public | F11: 4.1 | G11: =VLOOKUP(B11, 'Slope Ratings'!$A$2:$C$147, 2, TRUE) -> 121 | H11: 214 | J11: 42.473851 | K11: -83.568365 | L11: =INDEX('course_coordinates (1)'!$D$2:$D$145,MATCH('Main Data'!N117,'course_coordinates (1)'!$A$2:$A$145,0)) -> 42.473851 | M11: =INDEX('course_coordinates (1)'!$E$2:$E$145,MATCH('Main Data'!N117,'course_coordinates (1)'!$A$2:$A$145,0)) -> -83.568365 | N11: Bushwood Golf Course
A12: 1 | B12: Brookwood | C12: Rochester Hills | D12: Oakland | E12: Private | F12: 4.6 | G12: =VLOOKUP(B12, 'Slope Ratings'!$A$2:$C$147, 2, TRUE) -> 121 | H12: 52 | J12: 42.745893 | K12: -83.530674 | L12: =INDEX('course_coordinates (1)'!$D$2:$D$145,MATCH('Main Data'!N104,'course_coordinates (1)'!$A$2:$A$145,0)) -> 42.745893 | M12: =INDEX('course_coordinates (1)'!$E$2:$E$145,MATCH('Main Data'!N104,'course_coordinates (1)'!$A$2:$A$145,0)) -> -83.530674 | N12: Cedar Glen Golf and Outing
A13: 104 | B13: Bruce Hills | C13: Bruce Township | D13: Macomb | E13: Public | F13: 3.9 | G13: =VLOOKUP(B13, 'Slope Ratings'!$A$2:$C$147, 2, TRUE) -> 121 | H13: 187 | J13: 42.51959 | K13: -83.323322 | L13: =INDEX('course_coordinates (1)'!$D$2:$D$145,MATCH('Main Data'!N33,'course_coordinates (1)'!$A$2:$A$145,0)) -> 42.51959 | M13: =INDEX('course_coordinates (1)'!$E$2:$E$145,MATCH('Main Data'!N33,'course_coordinates (1)'!$A$2:$A$145,0)) -> -83.323322 | N13: Chandler Park Golf Course
A14: 93 | B14: Bushwood | C14: Northville | D14: Wayne* | E14: Public | F14: 4.3 | G14: =VLOOKUP(B14, 'Slope Ratings'!$A$2:$C$147, 2, TRUE) -> 117 | H14: 113 | J14: 42.806509 | K14: -83.244294 | L14: =INDEX('course_coordinates (1)'!$D$2:$D$145,MATCH('Main Data'!N77,'course_coordinates (1)'!$A$2:$A$145,0)) -> 42.806509 | M14: =INDEX('course_coordinates (1)'!$E$2:$E$145,MATCH('Main Data'!N77,'course_coordinates (1)'!$A$2:$A$145,0)) -> -83.244294 | N14: Copper Creek Golf Course
A15: 28 | B15: Cedar Glen | C15: New Baltimore | D15: Macomb | E15: Public | F15: 3.7 | G15: =VLOOKUP(B15, 'Slope Ratings'!$A$2:$C$147, 2, TRUE) -> 117 | H15: 285 | J15: 42.735314 | K15: -83.038512 | L15: =INDEX('course_coordinates (1)'!$D$2:$D$145,MATCH('Main Data'!N35,'course_coordinates (1)'!$A$2:$A$145,0)) -> 42.735314 | M15: =INDEX('course_coordinates (1)'!$E$2:$E$145,MATCH('Main Data'!N35,'course_coordinates (1)'!$A$2:$A$145,0)) -> -83.038512 | N15: Copper Hills Golf Club
A16: 53 | B16: Chandler Park | C16: Detroit | D16: Wayne | E16: Public | F16: 4.2 | G16: =VLOOKUP(B16, 'Slope Ratings'!$A$2:$C$147, 2, TRUE) -> 124 | H16: 298 | J16: 42.302699 | K16: -83.725076 | L16: =INDEX('course_coordinates (1)'!$D$2:$D$145,MATCH('Main Data'!N60,'course_coordinates (1)'!$A$2:$A$145,0)) -> 42.302699 | M16: =INDEX('course_coordinates (1)'!$E$2:$E$145,MATCH('Main Data'!N60,'course_coordinates (1)'!$A$2:$A$145,0)) -> -83.725076 | N16: Country Club of Detroit
A17: 29 | B17: Cherry Creek | C17: Shelby Township | D17: Macomb | E17: Public | F17: 4.5 | G17: =VLOOKUP(B17, 'Slope Ratings'!$A$2:$C$147, 2, TRUE) -> 124 | H17: 1030 | J17: 42.685237 | K17: -83.149237 | L17: =INDEX('course_coordinates (1)'!$D$2:$D$145,MATCH('Main Data'!N40,'course_coordinates (1)'!$A$2:$A$145,0)) -> 42.685237 | M17: =INDEX('course_coordinates (1)'!$E$2:$E$145,MATCH('Main Data'!N40,'course_coordinates (1)'!$A$2:$A$145,0)) -> -83.149237 | N17: Coyote Golf Club
A18: 54 | B18: Copper Creek | C18: Farmington Hills | D18: Oakland | E18: Public | F18: 4.2 | G18: =VLOOKUP(B18, 'Slope Ratings'!$A$2:$C$147, 2, TRUE) -> 139 | H18: 205 | J18: 42.676976 | K18: -83.021367 | L18: =INDEX('course_coordinates (1)'!$D$2:$D$145,MATCH('Main Data'!N130,'course_coordinates (1)'!$A$2:$A$145,0)) -> 42.676976 | M18: =INDEX('course_coordinates (1)'!$E$2:$E$145,MATCH('Main Data'!N130,'course_coordinates (1)'!$A$2:$A$145,0)) -> -83.021367 | N18: Dearborn Country Club
A19: 67 | B19: Copper Hills | C19: Oxford | D19: Oakland | E19: Public | F19: 3.9 | G19: =VLOOKUP(B19, 'Slope Ratings'!$A$2:$C$147, 2, TRUE) -> 139 | H19: 304 | J19: 42.414724 | K19: -82.894073 | L19: =INDEX('course_coordinates (1)'!$D$2:$D$145,MATCH('Main Data'!N16,'course_coordinates (1)'!$A$2:$A$145,0)) -> 42.414724 | M19: =INDEX('course_coordinates (1)'!$E$2:$E$145,MATCH('Main Data'!N16,'course_coordinates (1)'!$A$2:$A$145,0)) -> -82.894073 | N19: Dearborn Hills Golf Course
A20: 108 | B20: Country Club of Detroit | C20: Grosse Pointe Farms | D20: Wayne | E20: Private | F20: 4.6 | G20: =VLOOKUP(B20, 'Slope Ratings'!$A$2:$C$147, 2, TRUE) -> 139 | H20: 269 | J20: 42.482576 | K20: -83.419117 | L20: =INDEX('course_coordinates (1)'!$D$2:$D$145,MATCH('Main Data'!N25,'course_coordinates (1)'!$A$2:$A$145,0)) -> 42.482576 | M20: =INDEX('course_coordinates (1)'!$E$2:$E$145,MATCH('Main Data'!N25,'course_coordinates (1)'!$A$2:$A$145,0)) -> -83.419117 | N20: Detroit Golf Club
A21: 78 | B21: Coyote | C21: New Hudson | D21: Oakland | E21: Public | F21: 4.1 | G21: =VLOOKUP(B21, 'Slope Ratings'!$A$2:$C$147, 2, TRUE) -> 139 | H21: 287 | J21: 42.317751 | K21: -83.254531 | L21: =INDEX('course_coordinates (1)'!$D$2:$D$145,MATCH('Main Data'!N18,'course_coordinates (1)'!$A$2:$A$145,0)) -> 42.317751 | M21: =INDEX('course_coordinates (1)'!$E$2:$E$145,MATCH('Main Data'!N18,'course_coordinates (1)'!$A$2:$A$145,0)) -> -83.254531 | N21: Downing Farms Golf Course
A22: 115 | B22: Cracklewood | C22: Macomb | D22: Macomb | E22: Public | F22: 3.9 | G22: =VLOOKUP(B22, 'Slope Ratings'!$A$2:$C$147, 2, TRUE) -> 139 | H22: 130 | I22: 1989 | J22: 42.608721 | K22: -83.2319 | L22: =INDEX('course_coordinates (1)'!$D$2:$D$145,MATCH('Main Data'!N46,'course_coordinates (1)'!$A$2:$A$145,0)) -> 42.608721 | M22: =INDEX('course_coordinates (1)'!$E$2:$E$145,MATCH('Main Data'!N46,'course_coordinates (1)'!$A$2:$A$145,0)) -> -83.2319 | N22: Eagle Crest Golf Club
A23: 15 | B23: Dearborn CC | C23: Dearborn | D23: Wayne | E23: Private | F23: 4.5 | G23: =VLOOKUP(B23, 'Slope Ratings'!$A$2:$C$147, 2, TRUE) -> 139 | H23: 234 | J23: 42.723057 | K23: -82.75711 | L23: =INDEX('course_coordinates (1)'!$D$2:$D$145,MATCH('Main Data'!N69,'course_coordinates (1)'!$A$2:$A$145,0)) -> 42.723057 | M23: =INDEX('course_coordinates (1)'!$E$2:$E$145,MATCH('Main Data'!N69,'course_coordinates (1)'!$A$2:$A$145,0)) -> -82.75711 | N23: Edgewood Country Club
A24: 105 | B24: Dearborn Hills | C24: Dearborn | D24: Wayne | E24: Public | F24: 3.6 | G24: =VLOOKUP(B24, 'Slope Ratings'!$A$2:$C$147, 2, TRUE) -> 139 | H24: 148 | I24: 1922 | J24: 42.209915 | K24: -83.283211 | L24: =INDEX('course_coordinates (1)'!$D$2:$D$145,MATCH('Main Data'!N59,'course_coordinates (1)'!$A$2:$A$145,0)) -> 42.209915 | M24: =INDEX('course_coordinates (1)'!$E$2:$E$145,MATCH('Main Data'!N59,'course_coordinates (1)'!$A$2:$A$145,0)) -> -83.283211 | N24: Evergreen Hills Golf Course
A25: 91 | B25: Detroit Golf Club | C25: Detroit | D25: Wayne | E25: Private | F25: 4.7 | G25: =VLOOKUP(B25, 'Slope Ratings'!$A$2:$C$147, 2, TRUE) -> 139 | H25: 605 | I25: 1916 | J25: 42.498356 | K25: -83.424146 | L25: =INDEX('course_coordinates (1)'!$D$2:$D$145,MATCH('Main Data'!N14,'course_coordinates (1)'!$A$2:$A$145,0)) -> 42.498356 | M25: =INDEX('course_coordinates (1)'!$E$2:$E$145,MATCH('Main Data'!N14,'course_coordinates (1)'!$A$2:$A$145,0)) -> -83.424146 | N25: Farmington Hills Golf Club
A26: 58 | B26: Downing Farms | C26: Northville | D26: Wayne | E26: Public | F26: 3.8 | G26: =VLOOKUP(B26, 'Slope Ratings'!$A$2:$C$147, 2, TRUE) -> 139 | H26: 261 | J26: 42.585863 | K26: -83.382677 | L26: =INDEX('course_coordinates (1)'!$D$2:$D$145,MATCH('Main Data'!N76,'course_coordinates (1)'!$A$2:$A$145,0)) -> 42.585863 | M26: =INDEX('course_coordinates (1)'!$E$2:$E$145,MATCH('Main Data'!N76,'course_coordinates (1)'!$A$2:$A$145,0)) -> -83.382677 | N26: Fellows Creek Golf Club
A27: 2 | B27: Edgewood | C27: Commerce Township | D27: Oakland | E27: Private | F27: 4.7 | G27: =VLOOKUP(B27, 'Slope Ratings'!$A$2:$C$147, 2, TRUE) -> 139 | H27: 224 | J27: 42.834254 | K27: -83.277656 | L27: =INDEX('course_coordinates (1)'!$D$2:$D$145,MATCH('Main Data'!N7,'course_coordinates (1)'!$A$2:$A$145,0)) -> 42.834254 | M27: =INDEX('course_coordinates (1)'!$E$2:$E$145,MATCH('Main Data'!N7,'course_coordinates (1)'!$A$2:$A$145,0)) -> -83.277656 | N27: Fern Hill Golf Club
A28: 30 | B28: Evergreen Hills | C28: Southfield | D28: Oakland | E28: Public | F28: 4 | G28: =VLOOKUP(B28, 'Slope Ratings'!$A$2:$C$147, 2, TRUE) -> 139 | H28: 195 | J28: 42.682432 | K28: -82.850882 | L28: =INDEX('course_coordinates (1)'!$D$2:$D$145,MATCH('Main Data'!N97,'course_coordinates (1)'!$A$2:$A$145,0)) -> 42.682432 | M28: =INDEX('course_coordinates (1)'!$E$2:$E$145,MATCH('Main Data'!N97,'course_coordinates (1)'!$A$2:$A$145,0)) -> -82.850882 | N28: Fieldstone Golf Club
A29: 16 | B29: Farmington Hills | C29: Farmington Hills | D29: Oakland | E29: Public | F29: 4.2 | G29: =VLOOKUP(B29, 'Slope Ratings'!$A$2:$C$147, 2, TRUE) -> 139 | H29: 508 | J29: 42.653722 | K29: -83.448767 | L29: =INDEX('course_coordinates (1)'!$D$2:$D$145,MATCH('Main Data'!N124,'course_coordinates (1)'!$A$2:$A$145,0)) -> 42.653722 | M29: =INDEX('course_coordinates (1)'!$E$2:$E$145,MATCH('Main Data'!N124,'course_coordinates (1)'!$A$2:$A$145,0)) -> -83.448767 | N29: Forest Lake Country Club
A30: 31 | B30: Fellows Creek | C30: Canton Township | D30: Wayne | E30: Public | F30: 4.2 | G30: =VLOOKUP(B30, 'Slope Ratings'!$A$2:$C$147, 2, TRUE) -> 139 | H30: 409 | J30: 42.701271 | K30: -83.489377 | L30: =INDEX('course_coordinates (1)'!$D$2:$D$145,MATCH('Main Data'!N52,'course_coordinates (1)'!$A$2:$A$145,0)) -> 42.701271 | M30: =INDEX('course_coordinates (1)'!$E$2:$E$145,MATCH('Main Data'!N52,'course_coordinates (1)'!$A$2:$A$145,0)) -> -83.489377 | N30: Fountains Golf & Banquet
A31: 95 | B31: Fern Hill | C31: Clinton Township | D31: Macomb | E31: Public | F31: 4.1 | G31: =VLOOKUP(B31, 'Slope Ratings'!$A$2:$C$147, 2, TRUE) -> 139 | H31: 927 | I31: 1972 | J31: 42.792332 | K31: -83.057266 | L31: =INDEX('course_coordinates (1)'!$D$2:$D$145,MATCH('Main Data'!N42,'course_coordinates (1)'!$A$2:$A$145,0)) -> 42.792332 | M31: =INDEX('course_coordinates (1)'!$E$2:$E$145,MATCH('Main Data'!N42,'course_coordinates (1)'!$A$2:$A$145,0)) -> -83.057266 | N31: Fox Creek Golf Course
A32: 87 | B32: Fieldstone | C32: Auburn Hills | D32: Oakland | E32: Public | F32: 3.9 | G32: =VLOOKUP(B32, 'Slope Ratings'!$A$2:$C$147, 2, TRUE) -> 122 | H32: 432 | J32: 42.385981 | K32: -82.898042 | L32: =INDEX('course_coordinates (1)'!$D$2:$D$145,MATCH('Main Data'!N44,'course_coordinates (1)'!$A$2:$A$145,0)) -> 42.385981 | M32: =INDEX('course_coordinates (1)'!$E$2:$E$145,MATCH('Main Data'!N44,'course_coordinates (1)'!$A$2:$A$145,0)) -> -82.898042 | N32: Fox Hills Golf & Banquet Center
A33: 17 | B33: Forest Lake | C33: Bloomfield Township | D33: Oakland | E33: Private | F33: 4.6 | G33: =VLOOKUP(B33, 'Slope Ratings'!$A$2:$C$147, 2, TRUE) -> 122 | H33: 141 | J33: 42.618441 | K33: -83.525783 | L33: =INDEX('course_coordinates (1)'!$D$2:$D$145,MATCH('Main Data'!N9,'course_coordinates (1)'!$A$2:$A$145,0)) -> 42.618441 | M33: =INDEX('course_coordinates (1)'!$E$2:$E$145,MATCH('Main Data'!N9,'course_coordinates (1)'!$A$2:$A$145,0)) -> -83.525783 | N33: Franklin Hills Country Club
A34: 73 | B34: Fountains | C34: Village of Clarkston | D34: Oakland | E34: Public | F34: 4.4 | G34: =VLOOKUP(B34, 'Slope Ratings'!$A$2:$C$147, 2, TRUE) -> 122 | H34: 702 | J34: 42.519966 | K34: -83.570589 | L34: =INDEX('course_coordinates (1)'!$D$2:$D$145,MATCH('Main Data'!N65,'course_coordinates (1)'!$A$2:$A$145,0)) -> 42.519966 | M34: =INDEX('course_coordinates (1)'!$E$2:$E$145,MATCH('Main Data'!N65,'course_coordinates (1)'!$A$2:$A$145,0)) -> -83.570589 | N34: Gateway Golf Club
A35: 3 | B35: Fox Creek | C35: Livonia | D35: Wayne | E35: Public | F35: 4.4 | G35: =VLOOKUP(B35, 'Slope Ratings'!$A$2:$C$147, 2, TRUE) -> 122 | H35: 423 | J35: 42.42628 | K35: -83.126246 | L35: =INDEX('course_coordinates (1)'!$D$2:$D$145,MATCH('Main Data'!N20,'course_coordinates (1)'!$A$2:$A$145,0)) -> 42.42628 | M35: =INDEX('course_coordinates (1)'!$E$2:$E$145,MATCH('Main Data'!N20,'course_coordinates (1)'!$A$2:$A$145,0)) -> -83.126246 | N35: Glacier Club
A36: 124 | B36: Fox Hills | C36: Plymouth | D36: Wayne* | E36: Public | F36: 4.6 | G36: =VLOOKUP(B36, 'Slope Ratings'!$A$2:$C$147, 2, TRUE) -> 122 | H36: 1066 | I36: 1989 | J36: 42.790962 | K36: -82.959465 | L36: =INDEX('course_coordinates (1)'!$D$2:$D$145,MATCH('Main Data'!N82,'course_coordinates (1)'!$A$2:$A$145,0)) -> 42.790962 | M36: =INDEX('course_coordinates (1)'!$E$2:$E$145,MATCH('Main Data'!N82,'course_coordinates (1)'!$A$2:$A$145,0)) -> -82.959465 | N36: Glen Oaks Country Club
A37: 94 | B37: Franklin Hills | C37: Franklin | D37: Oakland | E37: Private | F37: 4.4 | G37: =VLOOKUP(B37, 'Slope Ratings'!$A$2:$C$147, 2, TRUE) -> 122 | H37: 135 | I37: 1926 | J37: 42.82732 | K37: -83.182912 | L37: =INDEX('course_coordinates (1)'!$D$2:$D$145,MATCH('Main Data'!N15,'course_coordinates (1)'!$A$2:$A$145,0)) -> 42.82732 | M37: =INDEX('course_coordinates (1)'!$E$2:$E$145,MATCH('Main Data'!N15,'course_coordinates (1)'!$A$2:$A$145,0)) -> -83.182912 | N37: Glen Oaks Golf Course
A38: 97 | B38: Gateway | C38: Romulus | D38: Wayne | E38: Public | F38: 4.2 | G38: =VLOOKUP(B38, 'Slope Ratings'!$A$2:$C$147, 2, TRUE) -> 122 | H38: 502 | J38: 42.564381 | K38: -83.354633 | L38: =INDEX('course_coordinates (1)'!$D$2:$D$145,MATCH('Main Data'!N108,'course_coordinates (1)'!$A$2:$A$145,0)) -> 42.564381 | M38: =INDEX('course_coordinates (1)'!$E$2:$E$145,MATCH('Main Data'!N108,'course_coordinates (1)'!$A$2:$A$145,0)) -> -83.354633 | N38: Glenhurst Golf Course
A39: 13 | B39: Glacier Club | C39: Washington | D39: Macomb | E39: Public | F39: 3.6 | G39: =VLOOKUP(B39, 'Slope Ratings'!$A$2:$C$147, 2, TRUE) -> 139 | H39: 379 | J39: 42.525915 | K39: -83.458842 | L39: =INDEX('course_coordinates (1)'!$D$2:$D$145,MATCH('Main Data'!N68,'course_coordinates (1)'!$A$2:$A$145,0)) -> 42.525915 | M39: =INDEX('course_coordinates (1)'!$E$2:$E$145,MATCH('Main Data'!N68,'course_coordinates (1)'!$A$2:$A$145,0)) -> -83.458842 | N39: Gowanie Golf Club
A40: 18 | B40: Glen Oaks | C40: Farmington Hills | D40: Oakland | E40: Public | F40: 4.4 | G40: =VLOOKUP(B40, 'Slope Ratings'!$A$2:$C$147, 2, TRUE) -> 139 | H40: 253 | J40: 42.418376 | K40: -83.604452 | L40: =INDEX('course_coordinates (1)'!$D$2:$D$145,MATCH('Main Data'!N21,'course_coordinates (1)'!$A$2:$A$145,0)) -> 42.418376 | M40: =INDEX('course_coordinates (1)'!$E$2:$E$145,MATCH('Main Data'!N21,'course_coordinates (1)'!$A$2:$A$145,0)) -> -83.604452 | N40: Great Oaks Country Club
...

Sheet County
A1: Golf Course | B1: County
A2: Bay Pointe | B2: Oakland
A3: Beacon Hill | B3: Oakland
A4: Bee Tee | B4: Macomb
A5: Bello Woods | B5: Macomb
A6: Birmingham CC | B6: Oakland
A7: Blackheath | B7: Oakland
A8: Bloomfield Hills CC | B8: Oakland
A9: Boulder Pointe | B9: Oakland
A10: Brae Burn | B10: Wayne
A11: Brentwood | B11: Oakland
A12: Brookwood | B12: Oakland
... A131: Wyandotte Shores | B131: Wayne

Sheet course_coordinates (1)
A1: course | B1: city | C1: county | D1: latitude | E1: longitude | F1: notes
A2: Cedar Glen Golf and Outing | B2: New Baltimore | C2: Macomb | D2: 42.705367 | E2: -82.747159
A3: Fern Hill Golf Club | B3: Clinton Township | C3: Macomb | D3: 42.582209 | E3: -82.942197
A4: Glacier Club | B4: Washington | C4: Macomb | D4: 42.735314 | E4: -83.038512
A5: Greystone Golf Club | B5: Washington | C5: Macomb | D5: 42.792332 | E5: -83.057266
A6: Maple Lane Golf Club | B6: Sterling Heights | C6: Macomb | D6: 42.537973 | E6: -83.007485
A7: Marsh Oaks Golf Club | B7: New Haven | C7: Macomb | D7: 42.723057 | E7: -82.75711
A8: Pine Valley Golf & Country Club | B8: Ray | C8: Macomb | D8: 42.790962 | E8: -82.959465
A9: Plum Brook Golf Club | B9: Sterling Heights | C9: Macomb | D9: 42.573854 | E9: -82.992733
A10: Rammler Golf Club | B10: Sterling Heights | C10: Macomb | D10: 42.57848 | E10: -82.986638
A11: Stony Creek Metropark Golf Course | B11: Shelby Township | C11: Macomb | D11: 42.717414 | E11: -83.10817
A12: Warfield Greens Golf Club | B12: Fraser | C12: Macomb | D12: 42.548214 | E12: -82.958743
A13: Selfridge Golf Course | B13: Selfridge ANGB | C13: Macomb | D13: 42.601828 | E13: -82.809727
... A76: Brae Burn Golf Club | B76: Plymouth Township | C76: Wayne* | D76: 42.391292 | E76: -83.551051
A77: Woodside Meadows | B77: Romulus | C77: Wayne | D77: 42.153229 | E77: -83.305986 | F77: Coords from clubhouse/restaurant listing
A78: Salem Hills Golf Club | B78: Northville | C78: Washtenaw | D78: 42.40484 | E78: -83.591614 | F78: Address is Northville but course is in Washtenaw County
A79: Water's Edge Golf Course | B79: Grosse Ile Township | C79: Wayne | D79: 42.125107 | E79: -83.172485
A80: Downing Farms Golf Course | B80: Northville | C80: Wayne* | D80: 42.418376 | E80: -83.604452
A81: Shenandoah Country Club | B81: West Bloomfield Township | C81: Oakland | D81: 42.557175 | E81: -83.397873
A82: Tam O'Shanter Country Club | B82: West Bloomfield Township | C82: Oakland | D82: 42.564381 | E82: -83.354633 | F82: Coords from pro shop listing - accurate location
A83: Katke-Cousins Golf Course | B83: Rochester Hills | C83: Oakland | D83: 42.664303 | E83: -83.20357
A84: Bee Tee Golf Course | B84: Macomb | C84: Macomb | D84: 42.647578 | E84: -82.88073
A85: Scalawags Golf Club | B85: New Baltimore | C85: Macomb | D85: 42.682432 | E85: -82.850882 | F85: CLOSED per Google reviews
A86: Tanglewood Golf Club | B86: South Lyon | C86: Oakland | D86: 42.455079 | E86: -83.578208
A87: Romeo Golf & Country Club | B87: Washington | C87: Macomb | D87: 42.796393 | E87: -82.986443 | F87: VERIFY - Google listing shows possibly closed
A88: Red Oaks Golf Course | B88: Madison Heights | C88: Oakland | D88: 42.509387 | E88: -83.105302
A89: Fox Hills Golf & Banquet Center | D89: 42.362859 | E89: -83.593107
A90: Northville Hills Golf Club | D90: 42.400437 | E90: -83.495901
A91: Links of Novi | D91: 42.46279 | E91: -83.543695
A92: Hilltop Golf Course | D92: 42.3656 | E92: -83.504639
A93: Farmington Hills Golf Club | D93: 42.482576 | E93: -83.419117
A94: Maples Golf Club | D94: 42.525915 | E94: -83.458842
A95: Copper Creek Golf Course | D95: 42.498356 | E95: -83.424146
A96: Glen Oaks Golf Course | D96: 42.514367 | E96: -83.352646
A97: Fox Creek Golf Course | D97: 42.427213 | E97: -83.398248
A98: Whispering Willows Golf Course | D98: 42.437731 | E98: -83.412829
A99: Glenhurst Golf Course | D99: 42.41393 | E99: -83.290976
A100: Western Golf & Country Club | D100: 42.393538 | E100: -83.299947
... A145: Somerset Golf Club | D145: 42.558334 | E145: -83.180168

Sheet Google Ratings
A1: course | B1: google_rating | C1: google_reviews
A2: Bay Pointe Golf Club | B2: 3.9 | C2: 212
A3: Beacon Hill Golf Club | B3: 4.3 | C3: 283
A4: Bee Tee Golf Course | B4: 3.7 | C4: 233
A5: Bello Woods Golf Course | B5: 3.9 | C5: 403
A6: Birmingham Country Club | B6: 4.7 | C6: 178
A7: Blackheath Golf Club | B7: 3.7 | C7: 377
A8: Bloomfield Hills Country Club | B8: 4.4 | C8: 122
A9: Boulder Pointe Golf Club | B9: 4.3 | C9: 503
A10: Brae Burn Golf Club | B10: 3.7 | C10: 243
A11: Brentwood Golf Club | B11: 4.1 | C11: 214
A12: Brookwood | B12: 4.6 | C12: 52
A13: Bruce Hills Public Golf Course | B13: 3.8 | C13: 186
... A38: Gateway Golf Club | B38: 4.2 | C38: 502
A39: Glacier Club
A40: Glen Oaks Golf Course | B40: 4.4 | C40: 255
A41: Glenhurst Golf Course | B41: 4.3 | C41: 407
A42: Gowanie Golf Club | B42: 4.7 | C42: 132
A43: Great Oaks Country Club | B43: 4.6 | C43: 197
A44: Greystone Golf Club | B44: 4.4 | C44: 647
A45: Grosse Ile Golf & Country Club | B45: 4.6 | C45: 182
A46: Grosse Pointe Club (Little Club) | B46: 4.5 | C46: 43
A47: Heather Highlands Golf Club | B47: 2.8 | C47: 170
A48: Heather Hills Golf Club | B48: 4.5 | C48: 331
A49: Heathers Club of Bloomfield | B49: 4.6 | C49: 282
A50: Hickory Hill Golf Course | B50: 4 | C50: 126
A51: Hickory Hollow Golf Club | B51: 4.1 | C51: 378
... A128: Wyandotte Shores Golf Course | B128: 4.4 | C128: 207

Sheet Slope Ratings
A1: Golf Course | B1: Highest/Championship Tee Slope | C1: Standard/Forward Tee Slope
A2: Bello Woods Golf Course | B2: 121 | C2: 110 | D2: =VLOOKUP(A2, 'Main Data'!#REF!, 1, FALSE) -> #REF!
A3: Bruce Hills Public Golf Course | B3: 117 | C3: 106 | D3: =VLOOKUP(A3, 'Main Data'!#REF!, 1, FALSE) -> #REF!
A4: Cedar Glen Golf and Outing | B4: 124 | C4: 116 | D4: =VLOOKUP(A4, 'Main Data'!#REF!, 1, FALSE) -> #REF!
A5: Cherry Creek Golf Club | B5: 139 | C5: 124 | D5: =VLOOKUP(A5, 'Main Data'!#REF!, 1, FALSE) -> #REF!
A6: Fern Hill Golf Club | B6: 122 | C6: 112 | D6: =VLOOKUP(A6, 'Main Data'!#REF!, 1, FALSE) -> #REF!
A7: Glacier Club | B7: 139 | C7: N/A | D7: =VLOOKUP(A7, 'Main Data'!#REF!, 1, FALSE) -> #REF!
A8: Greystone Golf Club | B8: 143 | C8: 139 | D8: =VLOOKUP(A8, 'Main Data'!#REF!, 1, FALSE) -> #REF!
A9: Maple Lane Golf Club | B9: NA | C9: 111 | D9: =VLOOKUP(A9, 'Main Data'!#REF!, 1, FALSE) -> #REF!
A10: Pine Valley Golf & Country Club | B10: 122 | C10: 121 | D10: =VLOOKUP(A10, 'Main Data'!#REF!, 1, FALSE) -> #REF!
A11: Plum Brook Golf Club | B11: 127 | C11: 117 | D11: =VLOOKUP(A11, 'Main Data'!#REF!, 1, FALSE) -> #REF!
A12: Stony Creek Metropark Golf Course | B12: 131 | C12: 126 | D12: =VLOOKUP(A12, 'Main Data'!#REF!, 1, FALSE) -> #REF!
A13: Selfridge Golf Course | B13: 128 | C13: 122 | D13: =VLOOKUP(A13, 'Main Data'!#REF!, 1, FALSE) -> #REF!
A14: Coyote Golf Club | B14: 141 | C14: 133 | D14: =VLOOKUP(A14, 'Main Data'!#REF!, 1, FALSE) -> #REF!
A15: Cracklewood Golf Club | B15: 127 | C15: 121 | D15: =VLOOKUP(A15, 'Main Data'!#REF!, 1, FALSE) -> #REF!
A16: Heather Hills Golf Club | B16: 120 | C16: 113 | D16: =VLOOKUP(A16, 'Main Data'!#REF!, 1, FALSE) -> #REF!
A17: Hickory Hollow Golf Club | B17: 121 | C17: 114 | D17: =VLOOKUP(A17, 'Main Data'!#REF!, 1, FALSE) -> #REF!
A18: Sycamore Hills Golf Club | B18: 126 | C18: 118 | D18: =VLOOKUP(A18, 'Main Data'!#REF!, 1, FALSE) -> #REF!
A19: The Orchards Golf Club | B19: 136 | C19: 128 | D19: =VLOOKUP(A19, 'Main Data'!#REF!, 1, FALSE) -> #REF!
A20: Gowanie Golf Club | B20: 130 | C20: 124 | D20: =VLOOKUP(A20, 'Main Data'!#REF!, 1, FALSE) -> #REF!
A21: Birmingham Country Club | B21: 135 | C21: 129 | D21: =VLOOKUP(A21, 'Main Data'!#REF!, 1, FALSE) -> #REF!
... A65: Springdale Golf Course | B65: 115 | C65: 107 | D65: =VLOOKUP(A65, 'Main Data'!#REF!, 1, FALSE) -> #REF!
A66: Little Myth Par 3 Golf Course | B66: N/A | C66: N/A | D66: =VLOOKUP(A66, 'Main Data'!#REF!, 1, FALSE) -> #REF!
A67: Copper Creek Golf Course | B67: 122 | C67: 114 | D67: =VLOOKUP(A67, 'Main Data'!#REF!, 1, FALSE) -> #REF!
A68: Evergreen Hills Golf Course | B68: 115 | C68: 108 | D68: =VLOOKUP(A68, 'Main Data'!#REF!, 1, FALSE) -> #REF!
A69: Farmington Hills Golf Club | B69: 126 | C69: 118 | D69: =VLOOKUP(A69, 'Main Data'!#REF!, 1, FALSE) -> #REF!
A70: Hampton Golf Club | B70: N/A | C70: N/A | D70: =VLOOKUP(A70, 'Main Data'!#REF!, 1, FALSE) -> #REF!
A71: Lincoln Hills Golf Course | B71: 118 | C71: 110 | D71: =VLOOKUP(A71, 'Main Data'!#REF!, 1, FALSE) -> #REF!
A72: Links of Novi | B72: 136 | C72: 127 | D72: =VLOOKUP(A72, 'Main Data'!#REF!, 1, FALSE) -> #REF!
A73: Maples Golf Club | B73: 120 | C73: 112 | D73: =VLOOKUP(A73, 'Main Data'!#REF!, 1, FALSE) -> #REF!
A74: Pine Trace Golf Club | B74: 137 | C74: 129 | D74: =VLOOKUP(A74, 'Main Data'!#REF!, 1, FALSE) -> #REF!
A75: Rackham Golf Course | B75: 122 | C75: 115 | D75: =VLOOKUP(A75, 'Main Data'!#REF!, 1, FALSE) -> #REF!
A76: Sanctuary Lake Golf Course | B76: 131 | C76: 123 | D76: =VLOOKUP(A76, 'Main Data'!#REF!, 1, FALSE) -> #REF!
A77: Somerset Golf Club | B77: 115 | C77: 107 | D77: =VLOOKUP(A77, 'Main Data'!#REF!, 1, FALSE) -> #REF!
A78: Sylvan Glen Golf Course | B78: 121 | C78: 114 | D78: =VLOOKUP(A78, 'Main Data'!#REF!, 1, FALSE) -> #REF!
A79: Oakhurst Golf & Country Club | B79: 140 | C79: 132 | D79: =VLOOKUP(A79, 'Main Data'!#REF!, 1, FALSE) -> #REF!
A80: Paint Creek Country Club | B80: 135 | C80: 127 | D80: =VLOOKUP(A80, 'Main Data'!#REF!, 1, FALSE) -> #REF!
A81: Prestwick Village Golf Club | B81: 139 | C81: 131 | D81: =VLOOKUP(A81, 'Main Data'!#REF!, 1, FALSE) -> #REF!
A82: Twin Lakes Golf Club | B82: 133 | C82: 125 | D82: =VLOOKUP(A82, 'Main Data'!#REF!, 1, FALSE) -> #REF!
... A106: Grosse Ile Golf & Country Club | B106: 134 | C106: 127 | D106: =VLOOKUP(A106, 'Main Data'!#REF!, 1, FALSE) -> #REF!
...

Sheet Courses
A1: course_id | B1: name | C1: city | D1: county (auto) | E1: address | F1: latitude | G1: longitude | H1: google_rating | I1: google_reviews | J1: phone | K1: place_id | L1: type_provisional VERIFY | M1: holes | N1: par | O1: year_built | P1: architect | Q1: mgmt_company | R1: usga_course_rating | S1: usga_slope | T1: yardage_back_tees | U1: notes | V1: price_tier_PROVISIONAL
A2: GC001 | B2: Fox Hills Golf & Banquet Center | C2: Plymouth | D2: Washtenaw | E2: 8768 N Territorial Rd, Plymouth, MI 48170 | F2: 42.362859 | G2: -83.593107 | H2: 4.6 | I2: 1066 | J2: +1 734-453-7272 | K2: ChIJjWOjHaaqPIgR12NC271dU8E | L2: Public/Muni | M2: 18 | N2: 72 | O2: 1989 | P2: Arthur Hills | Q2: Heritage Golf Group | R2: 73.6 | S2: 137 | T2: 6783 | U2: Golden Fox (rated course); 63 holes total/3 courses; back-tee rating | V2: Premium (est)
A3: GC002 | B3: Northville Hills Golf Club | C3: Northville | D3: Wayne* | E3: 15565 Bay Hill Dr, Northville, MI 48168 | F3: 42.400437 | G3: -83.495901 | H3: 4.4 | I3: 490 | J3: +1 734-667-4653 | K3: ChIJO_OAko-sJIgRdCwWBiYnM-Q | L3: Public/Muni | M3: 18 | N3: 72 | O3: 2000 | P3: Arnold Palmer/Ed Seay | Q3: Wilson Golf Group | R3: 72.2 | S3: 132 | T3: 7003 | U3: back-tee; GolfPass lists 73.0/138 | V3: Premium (est)
A4: GC003 | B4: Links of Novi | C4: Novi | D4: Oakland | E4: 50395 W 10 Mile Rd, Novi, MI 48374 | F4: 42.46279 | G4: -83.543695 | H4: 4.2 | I4: 195 | J4: +1 248-380-9595 | K4: ChIJZ1YbznapJIgRBi7bF39kAlk | L4: Public/Muni | V4: Mid (est)
A5: GC004 | B5: Hilltop Golf Course | C5: Plymouth | D5: Wayne* | E5: 47000 Powell Rd, Plymouth, MI 48170 | F5: 42.3656 | G5: -83.504639 | H5: 3.7 | I5: 312 | J5: +1 734-453-9800 | K5: ChIJHxAyAlVTO4gRcKM_JlD_JQY | L5: Public/Muni | V5: Value (est)
A6: GC005 | B6: Farmington Hills Golf Club | C6: Farmington Hills | D6: Oakland | E6: 37777 11 Mile Ct, Farmington Hills, MI 48335 | F6: 42.482576 | G6: -83.419117 | H6: 4.2 | I6: 508 | J6: +1 248-473-1866 | K6: ChIJGVHo4yuwJIgRm4dX5W1PEgo | L6: Public/Muni | V6: Mid (est)
A7: GC006 | B7: Maples Golf Club | C7: Novi | D7: Oakland | E7: 31260 Wakefield Dr, Novi, MI 48377 | F7: 42.525915 | G7: -83.458842 | H7: 4.1 | I7: 205 | J7: +1 248-896-2765 | K7: ChIJtQo7UXmlJIgReC8qeci1x5s | L7: Public/Muni | V7: Value (est)
A8: GC007 | B8: Copper Creek Golf Course | C8: Farmington Hills | D8: Oakland | E8: 27925 Golf Pointe Blvd, Farmington Hills, MI 48331 | F8: 42.498356 | G8: -83.424146 | H8: 4.2 | I8: 205 | J8: +1 248-489-1777 | K8: ChIJPWtD7RSvJIgRhngiR9Lzris | L8: Public/Muni | V8: Mid (est)
A9: GC008 | B9: Glen Oaks Golf Course | C9: Farmington Hills | D9: Oakland | E9: 30500 W 13 Mile Rd, Farmington Hills, MI 48334 | F9: 42.514367 | G9: -83.352646 | H9: 4.4 | I9: 253 | J9: +1 248-851-8356 | K9: ChIJfbuszAu6JIgRkQv3A5yLIqA | L9: Public/Muni | V9: Mid (est)
A10: GC009 | B10: Fox Creek Golf Course | C10: Livonia | D10: Wayne | E10: 36000 7 Mile, Livonia, MI 48152 | F10: 42.427213 | G10: -83.398248 | H10: 4.4 | I10: 423 | J10: +1 248-471-3400 | K10: ChIJf9Olgj2yJIgR88LX0eoZBtY | L10: Public/Muni | V10: Mid (est)
A11: GC010 | B11: Whispering Willows Golf Course | C11: Livonia | D11: Wayne | E11: 20500 Newburgh Rd, Livonia, MI 48152 | F11: 42.437731 | G11: -83.412829 | H11: 4.2 | I11: 362 | J11: +1 248-476-4493 | K11: ChIJv4yllhyyJIgRebVlXt8UjeI | L11: Public/Muni | V11: Mid (est)
A12: GC011 | B12: Glenhurst Golf Course | C12: Redford Township | D12: Wayne | E12: 25345 W 6 Mile Rd, Redford Township, MI 48240 | F12: 42.41393 | G12: -83.290976 | H12: 4.3 | I12: 405 | J12: +1 313-592-8758 | K12: ChIJHR6597S1JIgR6e75-64nhWY | L12: Public/Muni | V12: Value (est)
A13: GC012 | B13: Western Golf & Country Club | C13: Redford Township | D13: Wayne | E13: 14600 Kinloch St, Redford Township, MI 48239 | F13: 42.393538 | G13: -83.299947 | H13: 4.6 | I13: 214 | J13: +1 313-531-1240 | K13: ChIJKQ2AIFa0JIgR3ZOV_aXnOqI | L13: VERIFY | V13: Private (verify)
A14: GC013 | B14: Idyl Wyld Golf Course | C14: Livonia | D14: Wayne | E14: 35786 Five Mile Rd, Livonia, MI 48154 | F14: 42.397714 | G14: -83.396898 | H14: 3.8 | I14: 405 | J14: +1 734-464-6325 | K14: ChIJ82OfVF-yJIgRaJJ7Y7hw02w | L14: Public/Muni | V14: Value (est)
A15: GC014 | B15: Warren Valley Golf Course | C15: Dearborn Heights | D15: Wayne | E15: 26140 W Warren St, Dearborn Heights, MI 48127 | F15: 42.340947 | G15: -83.296723 | H15: 4 | I15: 527 | J15: +1 313-989-0135 | K15: ChIJd3oD0SZLO4gRJsgS8aTAtlA | L15: Public/Muni | V15: Value (est)
A16: GC015 | B16: TPC Michigan | C16: Dearborn | D16: Wayne | E16: 1 Nicklaus Dr, Dearborn, MI 48120 | F16: 42.306408 | G16: -83.200866 | H16: 4.6 | I16: 337 | J16: +1 313-436-3000 | K16: ChIJQaXCU1o0O4gR4ip3rVHm5Zo | L16: Private | M16: 18 | N16: 72 | O16: 1990 | P16: Jack Nicklaus | Q16: Invited (ClubCorp) | R16: 75.1 | S16: 148 | T16: 7071 | U16: private (resolved from VERIFY) | V16: Private
A17: GC016 | B17: Plum Hollow Country Club | C17: Southfield | D17: Oakland | E17: 21631 Lahser Rd, Southfield, MI 48033 | F17: 42.451144 | G17: -83.262468 | H17: 4.5 | I17: 242 | J17: +1 248-357-5353 | K17: ChIJEy7sqz22JIgRx4KqgGwskkw | L17: Private | V17: Private
A18: GC017 | B18: Rouge Park Golf Course | C18: Detroit | D18: Wayne | E18: 11701 Burt Rd, Detroit, MI 48228 | F18: 42.373478 | G18: -83.247219 | H18: 4.2 | I18: 380 | J18: +1 313-837-5900 | K18: ChIJVYlUQZ_KJIgRQIqLn-QWCgI | L18: Public/Muni | V18: Mid (fee)
A19: GC018 | B19: Chandler Park Golf Course | C19: Detroit | D19: Wayne | E19: 12801 Chandler Park Dr, Detroit, MI 48213 | F19: 42.397154 | G19: -82.97287 | H19: 4.2 | I19: 298 | J19: +1 313-331-7755 | K19: ChIJm7--0gHVJIgRPEa6H5uVJF4 | L19: Public/Muni | V19: Mid (fee)
A20: GC019 | B20: Evergreen Hills Golf Course | C20: Southfield | D20: Oakland | E20: 26000 Evergreen Rd, Southfield, MI 48076 | F20: 42.479117 | G20: -83.235713 | H20: 4 | I20: 195 | J20: +1 248-796-4666 | K20: ChIJ906KSTvIJIgRZJwIT0kVhM0 | L20: Public/Muni | V20: Value (est)
A21: GC020 | B21: Rackham Golf Course | C21: Huntington Woods | D21: Oakland | E21: 10100 W 10 Mile Rd, Huntington Woods, MI 48070 | F21: 42.476184 | G21: -83.163585 | H21: 3.7 | I21: 328 | J21: +1 248-543-4040 | K21: ChIJSd7SN33JJIgR4jhl_87GeUA | L21: Public/Muni | V21: Value (est)
A22: GC021 | B22: Lakes of Taylor Golf Course | C22: Taylor | D22: Wayne | E22: 25505 Northline Rd, Taylor, MI 48180 | F22: 42.209915 | G22: -83.283211 | H22: 4.3 | I22: 531 | J22: +1 734-287-2100 | K22: ChIJ8xEkxWVIO4gRYWuosy1hGe4 | L22: Public/Muni | V22: Mid (est)
A23: GC022 | B23: Detroit Golf Club | C23: Detroit | D23: Wayne | E23: 17911 Hamilton Rd, Detroit, MI 48203 | F23: 42.42628 | G23: -83.126246 | H23: 4.7 | I23: 605 | J23: +1 313-345-4400 | K23: ChIJbTJlSoDOJIgRkRStx64bV5M | L23: Private | M23: 36 | N23: 72 | O23: 1916 | P23: Donald Ross | R23: 73.6 | T23: 6936 | U23: North course; 36 holes; club est. 1899 | V23: Private
A24: GC023 | B24: Lincoln Hills Golf Course | C24: Birmingham | D24: Oakland | E24: 2666 W 14 Mile Rd, Birmingham, MI 48009 | F24: 42.53131 | G24: -83.247603 | H24: 4.4 | I24: 155 | J24: +1 248-530-1670 | K24: ChIJRaFGdInHJIgRCYMHNuZs6wQ | L24: Public/Muni | V24: Value (est)
A25: GC024 | B25: Stonebridge Golf Club | C25: Ann Arbor | D25: Washtenaw | E25: 1825 Clubhouse Dr, Ann Arbor, MI 48108 | F25: 42.210417 | G25: -83.764593 | H25: 4.6 | I25: 495 | J25: +1 734-429-8383 | K25: ChIJkTJkerO6PIgRwUnVaV_Hbcc | L25: Public/Muni | M25: 18 | N25: 72 | O25: 1991 | P25: Arthur Hills | Q25: independent (co-owner GM) | R25: 74.2 | S25: 135 | T25: 6932 | U25: back-tee; slope 131-135 varies by source | V25: Premium (est)
A26: GC025 | B26: Huron Hills Golf Course | C26: Ann Arbor | D26: Washtenaw | E26: 3465 E Huron River Dr, Ann Arbor, MI 48104 | F26: 42.271637 | G26: -83.696794 | H26: 4.1 | I26: 184 | J26: +1 734-794-6246 | K26: ChIJ2Q0y3NyuPIgRR7_UGrj7EYg | L26: Public/Muni | V26: Mid (fee)
A27: GC026 | B27: Leslie Park Golf Course | C27: Ann Arbor | D27: Washtenaw | E27: 2120 Traver Rd, Ann Arbor, MI 48105 | F27: 42.302699 | G27: -83.725076 | H27: 4.4 | I27: 390 | J27: +1 734-794-6245 | K27: ChIJtbFvo9OtPIgRmJaBmysLZXI | L27: Public/Muni | V27: Mid (fee)
A28: GC027 | B28: Washtenaw Golf Club | C28: Ypsilanti | D28: Washtenaw | E28: 2955 Packard St, Ypsilanti, MI 48197 | F28: 42.25233 | G28: -83.659152 | H28: 4.5 | I28: 296 | J28: +1 734-434-2150 | K28: ChIJtyZlRMKoPIgRtS6VGN8A8Us | L28: Public/Muni | V28: Mid (est)
A29: GC028 | B29: University of Michigan Golf Course | C29: Ann Arbor | D29: Washtenaw | E29: 500 E Stadium Blvd, Ann Arbor, MI 48104 | F29: 42.262821 | G29: -83.743736 | H29: 4.6 | I29: 361 | J29: +1 734-615-4653 | K29: ChIJvfjVlMuvPIgR43RxgKMGHVU | L29: VERIFY | V29: Premium (est)
A30: GC029 | B30: Eagle Crest Golf Club | C30: Ypsilanti | D30: Washtenaw | E30: 1201 S Huron St, Ypsilanti, MI 48197 | F30: 42.225658 | G30: -83.611868 | H30: 4.4 | I30: 741 | J30: +1 734-487-2441 | K30: ChIJFfHKCnKoPIgRZ160_Hi5t6U | L30: Public/Muni | V30: Premium (est)
A31: GC030 | B31: Lake Forest Golf Club | C31: Ann Arbor | D31: Washtenaw | E31: 3110 W Ellsworth Rd, Ann Arbor, MI 48103 | F31: 42.230116 | G31: -83.783347 | H31: 4.3 | I31: 198 | J31: +1 734-994-8580 | K31: ChIJ7SEgl3OwPIgRGEfFqSYHRi4 | L31: Public/Muni | V31: Mid (est)
A32: GC031 | B32: Green Oaks Golf Course | C32: Ypsilanti | D32: Washtenaw | E32: 1775 E Clark Rd, Ypsilanti, MI 48198 | F32: 42.259149 | G32: -83.570399 | H32: 4.1 | I32: 294 | J32: +1 734-485-0881 | K32: ChIJz3oFXjZWO4gR9_Azug-jmA0 | L32: Public/Muni | V32: Value (est)
A33: GC032 | B33: Pine View Golf Course | C33: Ypsilanti | D33: Washtenaw | E33: 5820 Stony Creek Rd, Ypsilanti, MI 48197 | F33: 42.205247 | G33: -83.624504 | H33: 3.8 | I33: 341 | J33: +1 734-481-0500 | K33: ChIJLUqD-cSnPIgRF913Oxgko-w | L33: Public/Muni | V33: Mid (fee)
